Workbook

Sheet README
A1: External Stress Test — Bangladesh, Pakistan, Vietnam
A3: Research question
A4: How did Bangladesh's exchange-rate and reserve pressure dynamics evolve around the May 2025 move toward a more flexible exchange-rate arrangement, and what does a simple external-shock stress test suggest about remaining vulnerabilities? This workbook implements the four-quarter stylized stress-test component.
A6: This is a stylized mechanical scenario exercise, NOT a forecast.
A7: No causal inference, econometric estimation, or forecasting is performed anywhere in this workbook. Every figure is the arithmetic result of applying a fixed, stated percentage shock to an observed historical baseline.
A9: Baseline period and horizon
A10: Baseline: 2025-Q2 to 2026-Q1 (the latest available common observed quarterly window). Horizon: 4 quarters.
A12: Locked shocks (see Scenarios sheet for the editable assumption cells)
A13: • Remittances: -10% (Bangladesh and Pakistan only)
A14: • Goods exports: -5% (all three countries)
A15: • Global energy-price proxy: +10%, mechanically translated into a stylized +10% increase in goods-import value
A17: On the energy-price proxy
... A41: • RESEARCH_LEDGER.md

Sheet Inputs
A1: INPUTS — Observed Baseline Data (verified, from master_analytical_dataset.csv)
A2: Blue = raw observed input. Values USD million unless noted. TOTAL rows use SUM formulas.
A4: BANGLADESH
A5: Quarter | B5: Goods Exports | C5: Goods Imports | D5: Current Account
A6: 2025-Q2 | B6: 10098.177 | C6: 15045.78 | D6: 743.97102
A7: 2025-Q3 | B7: 11085.62 | C7: 16799.4 | D7: -819.43608
A8: 2025-Q4 | B8: 11036.568 | C8: 16878.169 | D8: 233.40742
A9: 2026-Q1 | B9: 10256.846 | C9: 17870.616 | D9: 3.0670167
A10: TOTAL (4Q baseline) | B10: =SUM(B6:B9) -> 42477.212 | C10: =SUM(C6:C9) -> 66593.965 | D10: =SUM(D6:D9) -> 161.00937
A12: Bangladesh Remittances (monthly, for 12-month baseline)
A13: Month | B13: Remittances
A14: 2025-M04 | B14: 2752.33
A15: 2025-M05 | B15: 2969.56
A16: 2025-M06 | B16: 2822.53
A17: 2025-M07 | B17: 2477.87
A18: 2025-M08 | B18: 2421.89
A19: 2025-M09 | B19: 2685.56
A20: 2025-M10 | B20: 2562.44
A21: 2025-M11 | B21: 2889.73
A22: 2025-M12 | B22: 3223.67
A23: 2026-M01 | B23: 3171.63
A24: 2026-M02 | B24: 3019.45
A25: 2026-M03 | B25: 3752.21
A26: TOTAL (12-month baseline) | B26: =SUM(B14:B25) -> 34748.87
A28: PAKISTAN
A29: Quarter | B29: Goods Exports | C29: Goods Imports | D29: Current Account
A30: 2025-Q2 | B30: 7641 | C30: 15767 | D30: 164.0024
A31: 2025-Q3 | B31: 7847 | C31: 15489 | D31: -736.9998
A32: 2025-Q4 | B32: 7667 | C32: 15891 | D32: -623.9996
A33: 2026-Q1 | B33: 7758 | C33: 15310 | D33: 1646.9818
A34: TOTAL (4Q baseline) | B34: =SUM(B30:B33) -> 30913 | C34: =SUM(C30:C33) -> 62457 | D34: =SUM(D30:D33) -> 449.9848
A36: Pakistan Remittances (monthly, for 12-month baseline)
A37: Month | B37: Remittances
A38: 2025-M04 | B38: 3176.93
A39: 2025-M05 | B39: 3685.5885
A40: 2025-M06 | B40: 3406.3894
A41: 2025-M07 | B41: 3214.5145
A42: 2025-M08 | B42: 3138.1748
A43: 2025-M09 | B43: 3184.124
A44: 2025-M10 | B44: 3419.6136
...

Sheet Scenarios
A1: SCENARIOS — Locked Assumptions
A2: Yellow cells are the editable SHOCK assumption inputs. All downstream calculations reference these cells. The horizon (grey) is a fixed methodological parameter, not an editable scenario assumption — the Inputs sheet's baseline is built from a specific, hard-coded set of four quarters/twelve months, so changing this cell alone would not actually change which observations are pulled.
A4: Assumption | B4: Value | C4: Note
A5: Remittance shock (%) | B5: -0.1 | C5: Applied to Bangladesh and Pakistan only. Vietnam: N/A.
A6: Export shock (%) | B6: -0.05 | C6: Applied to all three countries.
A7: Global energy-price shock (%) | B7: 0.1 | C7: Magnitude of the global PCPS energy-price proxy shock. NOT country-specific.
A8: Import-price transmission / pass-through rate (%) | B8: 1 | C8: Real import quantities held constant; 100% pass-through into import VALUE. IMPOSED SIMPLIFYING ASSUMPTION, not an estimated coefficient.
A9: Horizon (quarters) | B9: 4 | C9: FIXED methodological parameter, not an editable scenario assumption — the baseline is the latest observed 4-quarter/12-month window, a structural choice tied to data availability, not a shock magnitude. Shown for reference only.
A11: Derived (formula, not an additional assumption):
A12: Import-value shock (%) = Energy shock x Transmission rate | B12: =B7*B8 -> 0.1
A14: "+10% global energy-price shock -> stylized +10% increase in goods-import value, holding real import quantities constant."
A15: This is an imposed simplifying assumption, NOT an estimated pass-through coefficient.

Sheet Calculations
A1: CALCULATIONS — Fully Formula-Driven (references Inputs and Scenarios sheets)
A2: Green = link to another sheet. Recalculates automatically if Inputs or Scenarios change.
A4: Metric | B4: Bangladesh | C4: Pakistan | D4: Vietnam
A6: Baseline (4-quarter / 12-month totals, linked from Inputs)
A7: Baseline goods exports | B7: =Inputs!B10 -> 42477.212 | C7: =Inputs!B34 -> 30913 | D7: =Inputs!B58 -> 494755
A8: Baseline goods imports | B8: =Inputs!C10 -> 66593.965 | C8: =Inputs!C34 -> 62457 | D8: =Inputs!C58 -> 458784
A9: Baseline current account | B9: =Inputs!D10 -> 161.00937 | C9: =Inputs!D34 -> 449.9848 | D9: =Inputs!D58 -> 31023
A10: Baseline remittances (12mo) | B10: =Inputs!B26 -> 34748.87 | C10: =Inputs!B50 -> 40589.861 | D10: N/A - UNRESOLVED
A12: Scenario shock magnitudes (linked from Scenarios)
A13: Remittance shock (%) | B13: =Scenarios!$B$5 -> -0.1 | C13: =Scenarios!$B$5 -> -0.1 | D13: N/A
A14: Export shock (%) | B14: =Scenarios!$B$6 -> -0.05 | C14: =Scenarios!$B$6 -> -0.05 | D14: =Scenarios!$B$6 -> -0.05
A15: Import-value shock (%) [energy x transmission] | B15: =Scenarios!$B$12 -> 0.1 | C15: =Scenarios!$B$12 -> 0.1 | D15: =Scenarios!$B$12 -> 0.1
A17: Shock amounts ($ million; negative = deterioration)
A18: Remittance shock amount | B18: =IF(ISNUMBER(B10),B10*B13,"N/A") -> -3474.887 | C18: =IF(ISNUMBER(C10),C10*C13,"N/A") -> -4058.9861 | D18: =IF(ISNUMBER(D10),D10*D13,"N/A") -> N/A
A19: Export shock amount | B19: =B7*B14 -> -2123.8606 | C19: =C7*C14 -> -1545.65 | D19: =D7*D14 -> -24737.75
A20: Import-price shock amount | B20: =-1*B8*B15 -> -6659.3965 | C20: =-1*C8*C15 -> -6245.7 | D20: =-1*D8*D15 -> -45878.4
A22: Combined deterioration and mechanically shocked current account
A23: Combined external-account deterioration | B23: =B18+B19+B20 -> -12258.144 | C23: =C18+C19+C20 -> -11850.336 | D23: =D19+D20 -> -70616.15
A24: Mechanically shocked current account | B24: =B9+B23 -> -12097.135 | C24: =C9+C23 -> -11400.351 | D24: =D9+D23 -> -39593.15
A25: Horizon (quarters) | B25: =Scenarios!$B$9 -> 4 | C25: =Scenarios!$B$9 -> 4 | D25: =Scenarios!$B$9 -> 4

Sheet Summary
A1: SUMMARY — Reviewer-Facing Results (all figures link to Calculations sheet)
A3: Country | B3: Baseline CA | C3: Remittance shock | D3: Export shock | E3: Import-price shock | F3: Combined deterioration | G3: Mechanically shocked CA
A4: Bangladesh | B4: =Calculations!B9 -> 161.00937 | C4: =Calculations!B18 -> -3474.887 | D4: =Calculations!B19 -> -2123.8606 | E4: =Calculations!B20 -> -6659.3965 | F4: =Calculations!B23 -> -12258.144 | G4: =Calculations!B24 -> -12097.135
A5: Pakistan | B5: =Calculations!C9 -> 449.9848 | C5: =Calculations!C18 -> -4058.9861 | D5: =Calculations!C19 -> -1545.65 | E5: =Calculations!C20 -> -6245.7 | F5: =Calculations!C23 -> -11850.336 | G5: =Calculations!C24 -> -11400.351
A6: Vietnam | B6: =Calculations!D9 -> 31023 | C6: =Calculations!D18 -> N/A | D6: =Calculations!D19 -> -24737.75 | E6: =Calculations!D20 -> -45878.4 | F6: =Calculations!D23 -> -70616.15 | G6: =Calculations!D24 -> -39593.15
A7: Vietnam combined scenario = Export + import-price only
A8: Note: Vietnam does not include a remittance shock because no suitable nationwide monthly remittance series was available.
A11: Bangladesh and Pakistan — individual scenario detail (mechanically shocked CA under each scenario)
A12: Country | B12: Scenario | C12: Mechanically shocked current account
A13: Bangladesh | B13: Baseline | C13: =Calculations!B9 -> 161.00937
A14: Bangladesh | B14: Remittance shock only | C14: =Calculations!B9+Calculations!B18 -> -3313.8776
A15: Bangladesh | B15: Export shock only | C15: =Calculations!B9+Calculations!B19 -> -1962.8512
A16: Bangladesh | B16: Import-price shock only | C16: =Calculations!B9+Calculations!B20 -> -6498.3871
A17: Bangladesh | B17: Combined | C17: =Calculations!B9+Calculations!B23 -> -12097.135
A19: Pakistan | B19: Baseline | C19: =Calculations!C9 -> 449.9848
A20: Pakistan | B20: Remittance shock only | C20: =Calculations!C9+Calculations!C18 -> -3609.0013
A21: Pakistan | B21: Export shock only | C21: =Calculations!C9+Calculations!C19 -> -1095.6652
A22: Pakistan | B22: Import-price shock only | C22: =Calculations!C9+Calculations!C20 -> -5795.7152
A23: Pakistan | B23: Combined | C23: =Calculations!C9+Calculations!C23 -> -11400.351

Sheet QA_Checks
A1: QA_CHECKS — Automated Verification
A2: All checks are formulas. Reference values (blue) are cited from the project's finalized files.
A4: Check | B4: Result | C4: Reference value | D4: Note
A5: 1. Bangladesh: 4 quarterly observations exist | B5: =IF(AND(COUNT(Inputs!B6:B9)=4,COUNT(Inputs!C6:C9)=4,COUNT(Inputs!D6:D9)=4),"PASS","FAIL") -> PASS
A6: 1. Pakistan: 4 quarterly observations exist | B6: =IF(AND(COUNT(Inputs!B30:B33)=4,COUNT(Inputs!C30:C33)=4,COUNT(Inputs!D30:D33)=4),"PASS","FAIL") -> PASS
A7: 1. Vietnam: 4 quarterly observations exist | B7: =IF(AND(COUNT(Inputs!B54:B57)=4,COUNT(Inputs!C54:C57)=4,COUNT(Inputs!D54:D57)=4),"PASS","FAIL") -> PASS
A8: 2. Bangladesh: 12 monthly remittance observations exist | B8: =IF(COUNT(Inputs!B14:B25)=12,"PASS","FAIL") -> PASS
A9: 2. Pakistan: 12 monthly remittance observations exist | B9: =IF(COUNT(Inputs!B38:B49)=12,"PASS","FAIL") -> PASS
A10: 3. Vietnam remittances are marked N/A, not zero | B10: =IF(AND(ISTEXT(Calculations!D10),ISTEXT(Calculations!D18),NOT(ISNUMBER(Calculations!D18))),"PASS","FAIL") -> PASS
A11: 3b. Vietnam remittance shock assumption (%) displays as text "N/A", not a numeric percentage | B11: =IF(AND(ISTEXT(Calculations!D13),Calculations!D13="N/A",NOT(ISNUMBER(Calculations!D13))),"PASS","FAIL") -> PASS
A12: 4. Bangladesh: combined = sum of individual shocks | B12: =IF(ABS(Calculations!B23-(Calculations!B18+Calculations!B19+Calculations!B20))<0.01,"PASS","FAIL") -> PASS
A13: 4. Pakistan: combined = sum of individual shocks | B13: =IF(ABS(Calculations!C23-(Calculations!C18+Calculations!C19+Calculations!C20))<0.01,"PASS","FAIL") -> PASS
A14: 4. Vietnam: combined = sum of applicable shocks (export+import-price only) | B14: =IF(ABS(Calculations!D23-(Calculations!D19+Calculations!D20))<0.01,"PASS","FAIL") -> PASS
A15: 5. Bangladesh: shocked CA = baseline CA + combined deterioration | B15: =IF(ABS(Calculations!B24-(Calculations!B9+Calculations!B23))<0.01,"PASS","FAIL") -> PASS
A16: 5. Pakistan: shocked CA = baseline CA + combined deterioration | B16: =IF(ABS(Calculations!C24-(Calculations!C9+Calculations!C23))<0.01,"PASS","FAIL") -> PASS
A17: 5. Vietnam: shocked CA = baseline CA + combined deterioration | B17: =IF(ABS(Calculations!D24-(Calculations!D9+Calculations!D23))<0.01,"PASS","FAIL") -> PASS
A18: 6. Horizon equals 4 quarters (all countries) | B18: =IF(AND(Calculations!B25=4,Calculations!C25=4,Calculations!D25=4,Scenarios!B9=4),"PASS","FAIL") -> PASS
A19: 7. Baseline inputs match data/derived/gate3_stress_test.csv
A20: Bangladesh baseline exports | B20: =IF(ROUND(Calculations!B7,2)=ROUND(C20,2),"PASS","FAIL") -> PASS | C20: 42477.21 | D20: Source: gate3_stress_test.csv
A21: Bangladesh baseline imports | B21: =IF(ROUND(Calculations!B8,2)=ROUND(C21,2),"PASS","FAIL") -> PASS | C21: 66593.96 | D21: Source: gate3_stress_test.csv
A22: Bangladesh baseline CA | B22: =IF(ROUND(Calculations!B9,2)=ROUND(C22,2),"PASS","FAIL") -> PASS | C22: 161.01 | D22: Source: gate3_stress_test.csv
A23: Bangladesh baseline remittances | B23: =IF(ROUND(Calculations!B10,2)=ROUND(C23,2),"PASS","FAIL") -> PASS | C23: 34748.87 | D23: Source: gate3_stress_test.csv
A24: Pakistan baseline exports | B24: =IF(ROUND(Calculations!C7,2)=ROUND(C24,2),"PASS","FAIL") -> PASS | C24: 30913 | D24: Source: gate3_stress_test.csv
A25: Pakistan baseline imports | B25: =IF(ROUND(Calculations!C8,2)=ROUND(C25,2),"PASS","FAIL") -> PASS | C25: 62457 | D25: Source: gate3_stress_test.csv
A26: Pakistan baseline CA | B26: =IF(ROUND(Calculations!C9,2)=ROUND(C26,2),"PASS","FAIL") -> PASS | C26: 449.98 | D26: Source: gate3_stress_test.csv
A27: Pakistan baseline remittances | B27: =IF(ROUND(Calculations!C10,2)=ROUND(C27,2),"PASS","FAIL") -> PASS | C27: 40589.86 | D27: Source: gate3_stress_test.csv
A28: Vietnam baseline exports | B28: =IF(ROUND(Calculations!D7,2)=ROUND(C28,2),"PASS","FAIL") -> PASS | C28: 494755 | D28: Source: gate3_stress_test.csv
A29: Vietnam baseline imports | B29: =IF(ROUND(Calculations!D8,2)=ROUND(C29,2),"PASS","FAIL") -> PASS | C29: 458784 | D29: Source: gate3_stress_test.csv
A30: Vietnam baseline CA | B30: =IF(ROUND(Calculations!D9,2)=ROUND(C30,2),"PASS","FAIL") -> PASS | C30: 31023 | D30: Source: gate3_stress_test.csv
A31: 8. Workbook results match the verified Gate 3 reference values (from gate3_stress_test.csv, consistent with FINAL_RESULTS_LOCKED.md R-005)
A32: Bangladesh combined deterioration | B32: =IF(ROUND(Calculations!B23,2)=ROUND(C32,2),"PASS","FAIL") -> PASS | C32: -12258.14 | D32: Source: gate3_stress_test.csv (consistent with FINAL_RESULTS_LOCKED.md R-005)
A33: Bangladesh shocked CA | B33: =IF(ROUND(Calculations!B24,2)=ROUND(C33,2),"PASS","FAIL") -> PASS | C33: -12097.13 | D33: Source: gate3_stress_test.csv (consistent with FINAL_RESULTS_LOCKED.md R-005)
A34: Pakistan combined deterioration | B34: =IF(ROUND(Calculations!C23,2)=ROUND(C34,2),"PASS","FAIL") -> PASS | C34: -11850.34 | D34: Source: gate3_stress_test.csv (consistent with FINAL_RESULTS_LOCKED.md R-005)
A35: Pakistan shocked CA | B35: =IF(ROUND(Calculations!C24,2)=ROUND(C35,2),"PASS","FAIL") -> PASS | C35: -11400.35 | D35: Source: gate3_stress_test.csv (consistent with FINAL_RESULTS_LOCKED.md R-005)
A36: Vietnam combined deterioration (2-shock) | B36: =IF(ROUND(Calculations!D23,2)=ROUND(C36,2),"PASS","FAIL") -> PASS | C36: -70616.15 | D36: Source: gate3_stress_test.csv (consistent with FINAL_RESULTS_LOCKED.md R-005)
A37: Vietnam shocked CA | B37: =IF(ROUND(Calculations!D24,2)=ROUND(C37,2),"PASS","FAIL") -> PASS | C37: -39593.15 | D37: Source: gate3_stress_test.csv (consistent with FINAL_RESULTS_LOCKED.md R-005)
A39: OVERALL RESULT | B39: =IF(COUNTIF(B5:B37,"FAIL")=0,"ALL CHECKS PASSED","REVIEW REQUIRED") -> ALL CHECKS PASSED
